[ 2023-10-18 14:15:41,195 ] werkzeug - INFO - [31m[1mWARNING: This is a development server. Do not use it in a production deployment. Use a production WSGI server instead.[0m
 * Running on all addresses (0.0.0.0)
 * Running on http://127.0.0.1:8080
 * Running on http://192.168.1.17:8080
[ 2023-10-18 14:15:41,195 ] werkzeug - INFO - [33mPress CTRL+C to quit[0m
[ 2023-10-18 14:15:44,007 ] werkzeug - INFO - 127.0.0.1 - - [18/Oct/2023 14:15:44] "GET / HTTP/1.1" 200 -
[ 2023-10-18 14:15:50,183 ] app - ERROR - Exception on /predict [POST]
Traceback (most recent call last):
  File "app.py", line 40, in predictRoute
    model = YOLO.load('yolov8/best.pt')
  File "C:\Users\ayana\miniconda3\envs\torch\lib\site-packages\torch\autograd\grad_mode.py", line 27, in decorate_context
    return func(*args, **kwargs)
  File "C:\Users\ayana\miniconda3\envs\torch\lib\site-packages\ultralytics\engine\model.py", line 182, in load
    self._check_is_pytorch_model()
AttributeError: 'str' object has no attribute '_check_is_pytorch_model'

During handling of the above exception, another exception occurred:

Traceback (most recent call last):
  File "C:\Users\ayana\miniconda3\envs\torch\lib\site-packages\flask\app.py", line 2529, in wsgi_app
    response = self.full_dispatch_request()
  File "C:\Users\ayana\miniconda3\envs\torch\lib\site-packages\flask\app.py", line 1825, in full_dispatch_request
    rv = self.handle_user_exception(e)
  File "C:\Users\ayana\miniconda3\envs\torch\lib\site-packages\flask_cors\extension.py", line 176, in wrapped_function
    return cors_after_request(app.make_response(f(*args, **kwargs)))
  File "C:\Users\ayana\miniconda3\envs\torch\lib\site-packages\flask\app.py", line 1823, in full_dispatch_request
    rv = self.dispatch_request()
  File "C:\Users\ayana\miniconda3\envs\torch\lib\site-packages\flask\app.py", line 1799, in dispatch_request
    return self.ensure_sync(self.view_functions[rule.endpoint])(**view_args)
  File "C:\Users\ayana\miniconda3\envs\torch\lib\site-packages\flask_cors\decorator.py", line 130, in wrapped_function
    resp = make_response(f(*args, **kwargs))
  File "app.py", line 59, in predictRoute
    AppException(e,)
TypeError: __init__() missing 1 required positional argument: 'error_detail'
[ 2023-10-18 14:15:50,188 ] werkzeug - INFO - 127.0.0.1 - - [18/Oct/2023 14:15:50] "[35m[1mPOST /predict HTTP/1.1[0m" 500 -
[ 2023-10-18 14:18:19,004 ] werkzeug - INFO - 127.0.0.1 - - [18/Oct/2023 14:18:19] "GET / HTTP/1.1" 200 -
